[2025-02-19 08:58:00,689] {taskinstance.py:1159} INFO - Dependencies all met for <TaskInstance: prediction_job.check_for_new_data scheduled__2025-02-19T08:56:00+00:00 [queued]>
[2025-02-19 08:58:00,701] {taskinstance.py:1159} INFO - Dependencies all met for <TaskInstance: prediction_job.check_for_new_data scheduled__2025-02-19T08:56:00+00:00 [queued]>
[2025-02-19 08:58:00,703] {taskinstance.py:1356} INFO - 
--------------------------------------------------------------------------------
[2025-02-19 08:58:00,704] {taskinstance.py:1357} INFO - Starting attempt 1 of 2
[2025-02-19 08:58:00,705] {taskinstance.py:1358} INFO - 
--------------------------------------------------------------------------------
[2025-02-19 08:58:00,722] {taskinstance.py:1377} INFO - Executing <Task(PythonOperator): check_for_new_data> on 2025-02-19 08:56:00+00:00
[2025-02-19 08:58:00,727] {standard_task_runner.py:52} INFO - Started process 686 to run task
[2025-02-19 08:58:00,730] {standard_task_runner.py:79} INFO - Running: ['***', 'tasks', 'run', 'prediction_job', 'check_for_new_data', 'scheduled__2025-02-19T08:56:00+00:00', '--job-id', '281', '--raw', '--subdir', 'DAGS_FOLDER/prediction_job.py', '--cfg-path', '/tmp/tmpq56c1ryo', '--error-file', '/tmp/tmpfkbqpa44']
[2025-02-19 08:58:00,732] {standard_task_runner.py:80} INFO - Job 281: Subtask check_for_new_data
[2025-02-19 08:58:00,760] {logging_mixin.py:115} WARNING - /home/***/.local/lib/python3.7/site-packages/***/configuration.py:470 DeprecationWarning: The sql_alchemy_conn option in [core] has been moved to the sql_alchemy_conn option in [database] - the old setting has been used, but please update your config.
[2025-02-19 08:58:00,826] {task_command.py:369} INFO - Running <TaskInstance: prediction_job.check_for_new_data scheduled__2025-02-19T08:56:00+00:00 [running]> on host 7ce684a335a4
[2025-02-19 08:58:00,903] {taskinstance.py:1571} INFO - Exporting the following env vars:
AIRFLOW_CTX_DAG_OWNER=***
AIRFLOW_CTX_DAG_ID=prediction_job
AIRFLOW_CTX_TASK_ID=check_for_new_data
AIRFLOW_CTX_EXECUTION_DATE=2025-02-19T08:56:00+00:00
AIRFLOW_CTX_TRY_NUMBER=1
AIRFLOW_CTX_DAG_RUN_ID=scheduled__2025-02-19T08:56:00+00:00
[2025-02-19 08:58:00,905] {taskinstance.py:1889} ERROR - Task failed with exception
Traceback (most recent call last):
  File "/home/airflow/.local/lib/python3.7/site-packages/airflow/operators/python.py", line 171, in execute
    return_value = self.execute_callable()
  File "/home/airflow/.local/lib/python3.7/site-packages/airflow/operators/python.py", line 189, in execute_callable
    return self.python_callable(*self.op_args, **self.op_kwargs)
  File "/opt/airflow/dags/prediction_job.py", line 41, in check_for_new_data
    files = os.listdir(GOOD_DATA_FOLDER)
FileNotFoundError: [Errno 2] No such file or directory: 'data/good_data'
[2025-02-19 08:58:00,924] {taskinstance.py:1400} INFO - Marking task as UP_FOR_RETRY. dag_id=prediction_job, task_id=check_for_new_data, execution_date=20250219T085600, start_date=20250219T085800, end_date=20250219T085800
[2025-02-19 08:58:00,937] {standard_task_runner.py:97} ERROR - Failed to execute job 281 for task check_for_new_data ([Errno 2] No such file or directory: 'data/good_data'; 686)
[2025-02-19 08:58:00,945] {local_task_job.py:156} INFO - Task exited with return code 1
[2025-02-19 08:58:00,981] {local_task_job.py:273} INFO - 0 downstream tasks scheduled from follow-on schedule check
