[2025-02-18 21:56:00,903] {taskinstance.py:1159} INFO - Dependencies all met for <TaskInstance: prediction_job.check_for_new_data scheduled__2025-02-18T21:54:00+00:00 [queued]>
[2025-02-18 21:56:00,913] {taskinstance.py:1159} INFO - Dependencies all met for <TaskInstance: prediction_job.check_for_new_data scheduled__2025-02-18T21:54:00+00:00 [queued]>
[2025-02-18 21:56:00,916] {taskinstance.py:1356} INFO - 
--------------------------------------------------------------------------------
[2025-02-18 21:56:00,917] {taskinstance.py:1357} INFO - Starting attempt 1 of 2
[2025-02-18 21:56:00,917] {taskinstance.py:1358} INFO - 
--------------------------------------------------------------------------------
[2025-02-18 21:56:00,941] {taskinstance.py:1377} INFO - Executing <Task(PythonOperator): check_for_new_data> on 2025-02-18 21:54:00+00:00
[2025-02-18 21:56:00,948] {standard_task_runner.py:52} INFO - Started process 567 to run task
[2025-02-18 21:56:00,954] {standard_task_runner.py:79} INFO - Running: ['***', 'tasks', 'run', 'prediction_job', 'check_for_new_data', 'scheduled__2025-02-18T21:54:00+00:00', '--job-id', '241', '--raw', '--subdir', 'DAGS_FOLDER/prediction_job.py', '--cfg-path', '/tmp/tmpnus8a5kb', '--error-file', '/tmp/tmpl4f3o5al']
[2025-02-18 21:56:00,956] {standard_task_runner.py:80} INFO - Job 241: Subtask check_for_new_data
[2025-02-18 21:56:00,987] {logging_mixin.py:115} WARNING - /home/***/.local/lib/python3.7/site-packages/***/configuration.py:470 DeprecationWarning: The sql_alchemy_conn option in [core] has been moved to the sql_alchemy_conn option in [database] - the old setting has been used, but please update your config.
[2025-02-18 21:56:01,038] {task_command.py:369} INFO - Running <TaskInstance: prediction_job.check_for_new_data scheduled__2025-02-18T21:54:00+00:00 [running]> on host 7ce684a335a4
[2025-02-18 21:56:01,140] {taskinstance.py:1571} INFO - Exporting the following env vars:
AIRFLOW_CTX_DAG_OWNER=***
AIRFLOW_CTX_DAG_ID=prediction_job
AIRFLOW_CTX_TASK_ID=check_for_new_data
AIRFLOW_CTX_EXECUTION_DATE=2025-02-18T21:54:00+00:00
AIRFLOW_CTX_TRY_NUMBER=1
AIRFLOW_CTX_DAG_RUN_ID=scheduled__2025-02-18T21:54:00+00:00
[2025-02-18 21:56:01,143] {taskinstance.py:1889} ERROR - Task failed with exception
Traceback (most recent call last):
  File "/home/airflow/.local/lib/python3.7/site-packages/airflow/operators/python.py", line 171, in execute
    return_value = self.execute_callable()
  File "/home/airflow/.local/lib/python3.7/site-packages/airflow/operators/python.py", line 189, in execute_callable
    return self.python_callable(*self.op_args, **self.op_kwargs)
  File "/opt/airflow/dags/prediction_job.py", line 41, in check_for_new_data
    files = os.listdir(GOOD_DATA_FOLDER)
FileNotFoundError: [Errno 2] No such file or directory: 'data/good_data'
[2025-02-18 21:56:01,167] {taskinstance.py:1400} INFO - Marking task as UP_FOR_RETRY. dag_id=prediction_job, task_id=check_for_new_data, execution_date=20250218T215400, start_date=20250218T215600, end_date=20250218T215601
[2025-02-18 21:56:01,188] {standard_task_runner.py:97} ERROR - Failed to execute job 241 for task check_for_new_data ([Errno 2] No such file or directory: 'data/good_data'; 567)
[2025-02-18 21:56:01,208] {local_task_job.py:156} INFO - Task exited with return code 1
[2025-02-18 21:56:01,248] {local_task_job.py:273} INFO - 0 downstream tasks scheduled from follow-on schedule check
