[2025-02-18 00:29:37,363] {taskinstance.py:1159} INFO - Dependencies all met for <TaskInstance: prediction_job.check_for_new_data manual__2025-02-18T00:24:35.195471+00:00 [queued]>
[2025-02-18 00:29:37,373] {taskinstance.py:1159} INFO - Dependencies all met for <TaskInstance: prediction_job.check_for_new_data manual__2025-02-18T00:24:35.195471+00:00 [queued]>
[2025-02-18 00:29:37,374] {taskinstance.py:1356} INFO - 
--------------------------------------------------------------------------------
[2025-02-18 00:29:37,375] {taskinstance.py:1357} INFO - Starting attempt 2 of 2
[2025-02-18 00:29:37,376] {taskinstance.py:1358} INFO - 
--------------------------------------------------------------------------------
[2025-02-18 00:29:37,391] {taskinstance.py:1377} INFO - Executing <Task(PythonOperator): check_for_new_data> on 2025-02-18 00:24:35.195471+00:00
[2025-02-18 00:29:37,395] {standard_task_runner.py:52} INFO - Started process 227 to run task
[2025-02-18 00:29:37,399] {standard_task_runner.py:79} INFO - Running: ['***', 'tasks', 'run', 'prediction_job', 'check_for_new_data', 'manual__2025-02-18T00:24:35.195471+00:00', '--job-id', '47', '--raw', '--subdir', 'DAGS_FOLDER/prediction_job.py', '--cfg-path', '/tmp/tmp5b5478y_', '--error-file', '/tmp/tmpfj99ov8g']
[2025-02-18 00:29:37,400] {standard_task_runner.py:80} INFO - Job 47: Subtask check_for_new_data
[2025-02-18 00:29:37,458] {task_command.py:369} INFO - Running <TaskInstance: prediction_job.check_for_new_data manual__2025-02-18T00:24:35.195471+00:00 [running]> on host 7ce684a335a4
[2025-02-18 00:29:37,530] {taskinstance.py:1571} INFO - Exporting the following env vars:
AIRFLOW_CTX_DAG_OWNER=***
AIRFLOW_CTX_DAG_ID=prediction_job
AIRFLOW_CTX_TASK_ID=check_for_new_data
AIRFLOW_CTX_EXECUTION_DATE=2025-02-18T00:24:35.195471+00:00
AIRFLOW_CTX_TRY_NUMBER=2
AIRFLOW_CTX_DAG_RUN_ID=manual__2025-02-18T00:24:35.195471+00:00
[2025-02-18 00:29:37,532] {taskinstance.py:1889} ERROR - Task failed with exception
Traceback (most recent call last):
  File "/home/airflow/.local/lib/python3.7/site-packages/airflow/operators/python.py", line 171, in execute
    return_value = self.execute_callable()
  File "/home/airflow/.local/lib/python3.7/site-packages/airflow/operators/python.py", line 189, in execute_callable
    return self.python_callable(*self.op_args, **self.op_kwargs)
  File "/opt/airflow/dags/prediction_job.py", line 41, in check_for_new_data
    files = os.listdir(GOOD_DATA_FOLDER)
FileNotFoundError: [Errno 2] No such file or directory: 'data/good_data'
[2025-02-18 00:29:37,548] {taskinstance.py:1400} INFO - Marking task as FAILED. dag_id=prediction_job, task_id=check_for_new_data, execution_date=20250218T002435, start_date=20250218T002937, end_date=20250218T002937
[2025-02-18 00:29:37,562] {standard_task_runner.py:97} ERROR - Failed to execute job 47 for task check_for_new_data ([Errno 2] No such file or directory: 'data/good_data'; 227)
[2025-02-18 00:29:37,572] {local_task_job.py:156} INFO - Task exited with return code 1
[2025-02-18 00:29:37,610] {local_task_job.py:273} INFO - 0 downstream tasks scheduled from follow-on schedule check
